#VRML_SIM R2021a utf8
WorldInfo {
  basicTimeStep 16
  coordinateSystem "NUE"
  contactProperties [
    ContactProperties {
      material2 "slippy"
      coulombFriction [
        0
      ]
    }
    ContactProperties {
      material2 "block"
      coulombFriction [
        0.01
      ]
    }
  ]
}
Viewpoint {
  orientation -0.011347045155972908 0.9964020670123657 0.08398907916933727 3.4281383474109863
  position -0.20579003561619186 0.2370624521816365 -0.7710802559671008
}
TexturedBackground {
}
TexturedBackgroundLight {
}
Floor {
  size 2.4 2.4
  appearance Asphalt {
  }
}
DEF Block_R1 Solid {
  translation 0.377 0.05 -0.9
  children [
    DEF BOX_R Shape {
      appearance PBRAppearance {
        baseColor 1 0 0
        metalness 0
      }
      geometry Box {
        size 0.05 0.05 0.05
      }
    }
  ]
  name "solid(4)"
  contactMaterial "box"
  boundingObject USE BOX_R
  physics Physics {
  }
}
DEF Block_R2 Solid {
  translation 1 0.05 0.3
  children [
    USE BOX_R
  ]
  name "solid(13)"
  contactMaterial "block"
  boundingObject USE BOX_R
  physics Physics {
  }
}
DEF Block_R3 Solid {
  translation -1 0.05 -0.5
  children [
    USE BOX_R
  ]
  name "solid(12)"
  boundingObject USE BOX_R
  physics Physics {
  }
}
DEF Block_R4 Solid {
  translation 0.1 0.05 1.1
  children [
    USE BOX_R
  ]
  name "solid(7)"
  boundingObject USE BOX_R
  physics Physics {
  }
}
DEF Block_B1 Solid {
  translation -1.1 0.05 1
  children [
    DEF BOX_B Shape {
      appearance PBRAppearance {
        baseColor 0 0 1
        metalness 0
      }
      geometry Box {
        size 0.05 0.05 0.05
      }
    }
  ]
  name "solid(8)"
  boundingObject USE BOX_B
  physics Physics {
  }
}
DEF Block_B2 Solid {
  translation -0.122619 0.05 0.684374
  children [
    USE BOX_B
  ]
  name "solid(9)"
  boundingObject USE BOX_B
  physics Physics {
  }
}
DEF Block_B3 Solid {
  translation -0.85 0.05 -0.2
  children [
    USE BOX_B
  ]
  name "solid(10)"
  boundingObject USE BOX_B
  physics Physics {
  }
}
DEF Block_B4 Solid {
  translation 1 0.05 0.7
  children [
    USE BOX_B
  ]
  name "solid(11)"
  boundingObject USE BOX_B
  physics Physics {
  }
}
DEF Floor_colour Solid {
  translation 1 0.0001 1
  children [
    Shape {
      appearance PBRAppearance {
        baseColor 1 0 0
      }
      geometry Plane {
        size 0.4 0.4
      }
    }
  ]
  name "solid(6)"
}
DEF Floor_colour Solid {
  translation 1 0.0001 -1
  children [
    Shape {
      appearance PBRAppearance {
        baseColor 0 0 1
      }
      geometry Plane {
        size 0.4 0.4
      }
    }
  ]
  name "solid(5)"
}
DEF WALL_1 Solid {
  translation 1.2 0.05 0
  children [
    DEF WALL_SHAPE Shape {
      appearance PBRAppearance {
        baseColor 0.12549 0.368627 0.729412
        roughness 1
        metalness 0
      }
      geometry Box {
        size 0.02 0.1 2.38
      }
    }
  ]
  boundingObject USE WALL_SHAPE
}
DEF WALL_2 Solid {
  translation -1.2 0.05 0
  rotation 0 -0.9999999999999999 0 0
  children [
    USE WALL_SHAPE
  ]
  name "solid(1)"
  boundingObject USE WALL_SHAPE
}
DEF WALL_3 Solid {
  translation 0 0.05 -1.2
  rotation 0 1 0 1.5708
  children [
    USE WALL_SHAPE
  ]
  name "solid(2)"
  boundingObject USE WALL_SHAPE
}
DEF WALL_4 Solid {
  translation 0 0.05 1.2
  rotation 0 1 0 1.5708
  children [
    USE WALL_SHAPE
  ]
  name "solid(3)"
  boundingObject USE WALL_SHAPE
}
Robot {
  translation 0.46 0.015 0
  children [
    Solid {
      children [
        DEF Box-Shape Shape {
          appearance DEF Colour PBRAppearance {
            baseColor 0 1 1
            metalness 0
          }
          geometry Mesh {
            url [
              "C:/Users/Jacob/Documents/IDP/Webots/Box_Shape.STL"
            ]
          }
        }
      ]
      boundingObject USE Box-Shape
      physics Physics {
      }
      recognitionColors [
        0 0 0
      ]
    }
    Transform {
      translation -0.02 0.0356 0.05
      rotation 0 0 1 1.5708
      children [
        HingeJoint {
          jointParameters HingeJointParameters {
            axis 0 -1 0
          }
          device [
            RotationalMotor {
            }
          ]
          endPoint Solid {
            rotation 0 -1 0 0
            children [
              DEF Wheel-Shape Shape {
                appearance USE Colour
                geometry Cylinder {
                  height 0.022
                  radius 0.05
                }
              }
            ]
            name "solid(4)"
            boundingObject USE Wheel-Shape
            physics Physics {
            }
          }
        }
      ]
    }
    Transform {
      translation 0.17 0.0356 0.05
      rotation 0 0 1 1.5708
      children [
        HingeJoint {
          jointParameters HingeJointParameters {
            axis 0 1 0
          }
          endPoint Solid {
            children [
              USE Wheel-Shape
            ]
            name "solid(1)"
            boundingObject USE Wheel-Shape
            physics Physics {
            }
          }
        }
      ]
    }
    Transform {
      translation 0.064 0 0.175
      rotation 1 0 0 3.14159
      children [
        Solid {
          children [
            DEF Bearing-Shape Shape {
              appearance USE Colour
              geometry Mesh {
                url [
                  "C:/Users/Jacob/Documents/IDP/Webots/Bearing.STL"
                ]
              }
            }
          ]
          name "solid(3)"
          boundingObject USE Bearing-Shape
          physics Physics {
            density 1000000
          }
        }
      ]
    }
    Transform {
      translation 0.05 0.0813 -0.072
      children [
        HingeJoint {
          jointParameters HingeJointParameters {
            anchor 0 0.025 0.172
          }
          device [
            RotationalMotor {
            }
          ]
          endPoint Solid {
            rotation 1 0 0 0
            children [
              DEF Arm1-Shape Shape {
                appearance USE Colour
                geometry Mesh {
                  url [
                    "C:/Users/Jacob/Documents/IDP/Webots/Arm1main.STL"
                  ]
                }
              }
            ]
            name "solid(5)"
            boundingObject USE Arm1-Shape
            physics Physics {
            }
          }
        }
      ]
    }
    Transform {
      translation 0.053 0.05706 -0.07213
      children [
        HingeJoint {
          jointParameters HingeJointParameters {
            anchor 0 0.0495 0.025
          }
          endPoint Solid {
            translation -1.843137617529855e-08 -8.933842306470263e-06 -6.158416737931521e-06
            rotation -0.9594485268236111 -0.245841459926458 -0.13791483225973197 1.1626725913960596e-06
            children [
              DEF Arm2-Shape Shape {
                appearance USE Colour
                geometry Mesh {
                  url [
                    "C:/Users/Jacob/Documents/IDP/Webots/Arm2lower.STL"
                  ]
                }
              }
              Transform {
                translation -0.026 -0.018 -0.005
                children [
                  Solid {
                    children [
                      DEF Claw1-Shape Shape {
                        appearance USE Colour
                        geometry Mesh {
                          url [
                            "C:/Users/Jacob/Documents/IDP/Webots/Grabber1upper.STL"
                          ]
                        }
                      }
                    ]
                    boundingObject USE Claw1-Shape
                    physics Physics {
                    }
                  }
                ]
              }
              SliderJoint {
                jointParameters JointParameters {
                  axis 1 0 0
                }
                device [
                  LinearMotor {
                  }
                ]
                endPoint Solid {
                  translation -0.02 -0.07 0.055
                  rotation 0 1 0 1.5708
                  children [
                    DEF Grabber1-Shape Shape {
                      appearance USE Colour
                      geometry Mesh {
                        url [
                          "C:/Users/Jacob/Documents/IDP/Webots/Grabber2claw.STL"
                        ]
                      }
                    }
                  ]
                  name "solid(1)"
                  boundingObject USE Grabber1-Shape
                  physics Physics {
                  }
                }
              }
              SliderJoint {
                jointParameters JointParameters {
                  axis 1 0 0
                }
                device [
                  LinearMotor {
                  }
                ]
                endPoint Solid {
                  translation 0.0650006961016294 -0.07 0
                  rotation 0 1 0 -1.5707953071795862
                  children [
                    USE Grabber1-Shape
                  ]
                  name "solid(2)"
                  boundingObject USE Grabber1-Shape
                  physics Physics {
                  }
                }
              }
            ]
            name "solid(2)"
            boundingObject USE Arm2-Shape
            physics Physics {
            }
          }
        }
      ]
    }
  ]
  physics Physics {
  }
  recognitionColors [
    0 0 0
  ]
}
IDP_Robot {
}
